Workbook

Sheet Portada
C9: TRABAJO FINAL DE INGENIERÍA
C21: Alumno: Gómez Avellaneda, Javier
C22: Legajo: B00074234-T1
C23: Docentes: Scali, Jorge — Vilaboa, Pablo
C24: Comisión: 5° A - Turno Noche
C25: Localización: Ciudad Autónoma de Buenos Aires
C26: Email: javieralejandro.gomezavellaneda@alumnos.uai.edu.ar

Sheet Indice
D2: Índice
D4: Hipótesis
D5: Proyección de ventas
D6: Anexo de capacidad operativa
D7: Modelo de ingresos
D8: Estructura de costos fijos
D9: Estructura de costos variables
D10: Estructura de costos de RRHH
D11: Modelo de egresos
D12: Modelo de inversión
D13: Amortizaciones
D14: Presupuesto financiero
... D19: Plan de contingencia

Sheet Hipótesis
E1: Hipótesis
B3: 1 - Descripción del negocio
B4: ShopMetrics es una Empresa de Base Tecnológica (EBT) que desarrolla y explota software propio bajo modalidad SaaS para el comercio minorista. El negocio no consiste en la venta de dispositivos de conteo, sino en la provisión de un ecosistema de medición del embudo comercial del local: cuántas personas pasan por delante, cuántas se detienen frente a la vidriera, cuántas entran y cuántas compran. Los datos se capturan con infraestructura propia instalada en el local (sensores de vidriera y contadores de puerta que publican únicamente cantidades, nunca imágenes) y se integran de forma automática con el sistema de punto de venta que el comercio ya utiliza; sobre esa base, modelos propios de Machine Learning convierten la medición en decisiones de exhibición, dotación de personal y horario de atención. El servicio se contrata con un abono mensual y un cargo de alta e instalación por única vez, y los equipos se entregan en comodato, de modo que el comercio no afronta inversión inicial. Todos los importes de este presupuesto están expresados en dólares.
B7: 2 - Mercado meta
B8: Comercios minoristas de indumentaria, textiles y calzado, de entre uno y cinco locales y hasta nueve ocupados, con local a la calle y vidriera a la vereda, ubicados en los ejes comerciales de mayor densidad del AMBA, con cabecera en el eje Avellaneda.
B11: Comercios | C11: Gasto promedio anual (USD) | D11: Total mercado (USD)
B12: 3400 | C12: 480 | D12: =B12*C12 -> 1632000
B15: 3 - Participación del mercado
B16: Participación del 15% del segmento objetivo al cierre del tercer año, con una progresión de 3% el primer año, 8% el segundo y 15% el tercero. La progresión es moderada porque se trata de un emprendimiento que recién arranca y porque el segmento ya está acotado por la segmentación: son 3.400 comercios de un solo rubro en los ejes relevados de la Ciudad de Buenos Aires. El salto del segundo al tercer año duplica la cartera, por lo que requiere un esfuerzo adicional de promoción que se refleja en el modelo de egresos.
A22: Evolución de la participación en el mercado
A23: Año | B23: Cantidad | C23: Porcentaje | D23: Total (USD)
A24: 2026 | B24: 102 comercios | C24: 0.03 | D24: =C24*$D$12 -> 48960
A25: 2027 | B25: 272 comercios | C25: 0.08 | D25: =C25*$D$12 -> 130560
A26: 2028 | B26: 510 comercios | C26: 0.15 | D26: =C26*$D$12 -> 244800
B31: Detalle: el gasto promedio anual de USD 480 por comercio corresponde a lo que un comercio minorista chico destina hoy a software de gestión y analítica. Se toma como referencia la lista de precios pública de Fudo, uno de los siete sistemas de punto de venta con los que la plataforma se integra, cuyo plan de entrada se ubica en el orden de los USD 40 mensuales por sucursal. La cantidad de 3.400 comercios surge de aplicar la participación del rubro Indumentaria, textiles y calzado (24,3%) sobre los 14.083 locales ocupados que releva el Instituto de Estadística y Censos de la Ciudad de Buenos Aires en sus ejes comerciales.
B33: 4 - Otros datos
B35: Líneas de servicios
C36: VERSIONES DEL SERVICIO
C39: Alta e instalación | D39: Abono mensual
B40: PROFUNDIDAD DE LAS LÍNEAS DE SERVICIOS | C40: Plan Básico | D40: Plan Básico
C43: Plan Vidriera | D43: Plan Vidriera
C46: Plan Cadena | D46: Plan Cadena
B56: Lista de precios (USD)
B57: Servicio | C57: Precio | D57: Detalle | E57: Modalidad de cobro
B58: Alta e instalación Plan Básico | C58: 25 | D58: Por única vez. Alta remota: conexión con el sistema de punto de venta y verificación de datos. No requiere visita al local. | E58: Cobro por única vez
B59: Alta e instalación Plan Vidriera | C59: 60 | D59: Por única vez. Visita al local: montaje del sensor de vidriera y del contador de puerta, conexión del punto de venta y prueba del embudo. | E59: Cobro por única vez
B60: Alta e instalación Plan Cadena | C60: 250 | D60: Por única vez. Instalación en hasta cinco locales de una misma cadena. | E60: Cobro por única vez
B61: Abono Plan Básico | C61: 15 | D61: Analítica de ventas por hora, ticket promedio y rotación, a partir del punto de venta. Sin dispositivos de conteo. Es la puerta de entrada comercial. | E61: Cobro mensual
B62: Abono Plan Vidriera | C62: 29 | D62: Embudo completo del local: pasan, se detienen, entran y compran, más comparación anónima contra el rubro y alertas automáticas. Es el plan principal. | E62: Cobro mensual
B63: Abono Plan Cadena | C63: 79 | D63: Hasta cinco locales: embudo por local, comparación entre sucursales y consolidado de toda la red. | E63: Cobro mensual

Sheet Proy. ventas
B1: Proyección de ventas
B5: Evolución de la participación | G5: Justificación ingresos
B6: 2026 | C6: 2027 | D6: 2028 | G6: Los ingresos no se distribuyen de manera uniforme en el año. El abono es mensual y las suscripciones se acumulan: el comercio que se da de alta en marzo sigue pagando en abril, de modo que el ingreso recurrente crece mes a mes aunque la cantidad de altas se mantenga constante. Los cargos de alta e instalación, en cambio, se cobran por única vez en el mes en que ingresa el comercio. El primer trimestre de 2026 tiene pocas altas porque se destina a poner a punto el proceso de instalación sobre los primeros comercios del eje Avellaneda; a partir de allí la captación crece de manera sostenida.
B7: =Hipótesis!C24 -> 0.03 | C7: =Hipótesis!C25 -> 0.08 | D7: =Hipótesis!C26 -> 0.15
B8: =Hipótesis!D24 -> 48960 | C8: =Hipótesis!D25 -> 130560 | D8: =Hipótesis!D26 -> 244800
A10: .
A15: Proyección de ventas 2026
A16: Producto | B16: Precio | C16: Anual | E16: Enero | G16: Febrero | I16: Marzo | K16: Abril | M16: Mayo | O16: Junio | Q16: Julio | S16: Agosto | U16: Septiembre | W16: Octubre | Y16: Noviembre | AA16: Diciembre
C17: Cantidad | D17: Ingresos | E17: =F32/$D$32 -> 0 | G17: =H32/$D$32 -> 0.0061831951 | I17: =J32/$D$32 -> 0.016824043 | K17: =L32/$D$32 -> 0.027896276 | M17: =N32/$D$32 -> 0.05492978 | O17: =P32/$D$32 -> 0.069021713 | Q17: =R32/$D$32 -> 0.086181278 | S17: =T32/$D$32 -> 0.10473086 | U17: =V32/$D$32 -> 0.12232181 | W17: =X32/$D$32 -> 0.1429804 | Y17: =Z32/$D$32 -> 0.16076307 | AA17: =AB32/$D$32 -> 0.20816757
E18: Cantidad | F18: Ingresos | G18: Cantidad | H18: Ingresos | I18: Cantidad | J18: Ingresos | K18: Cantidad | L18: Ingresos | M18: Cantidad | N18: Ingresos | O18: Cantidad | P18: Ingresos | Q18: Cantidad | R18: Ingresos | S18: Cantidad | T18: Ingresos | U18: Cantidad | V18: Ingresos | W18: Cantidad | X18: Ingresos | Y18: Cantidad | Z18: Ingresos | AA18: Cantidad | AB18: Ingresos
A19: =Hipótesis!$B$58 -> Alta e instalación Plan Básico | B19: =Hipótesis!C58 -> 25 | C19: =E19+G19+I19+K19+M19+O19+Q19+S19+U19+W19+Y19+AA19 -> 30 | D19: =B19*C19 -> 750 | E19: 0 | F19: =E19*$B$19 -> 0 | G19: 1 | H19: =G19*$B$19 -> 25 | I19: 1 | J19: =I19*$B$19 -> 25 | K19: 2 | L19: =K19*$B$19 -> 50 | M19: 2 | N19: =M19*$B$19 -> 50 | O19: 3 | P19: =O19*$B$19 -> 75 | Q19: 3 | R19: =Q19*$B$19 -> 75 | S19: 3 | T19: =S19*$B$19 -> 75 | U19: 4 | V19: =U19*$B$19 -> 100 | W19: 4 | X19: =W19*$B$19 -> 100 | Y19: 4 | Z19: =Y19*$B$19 -> 100 | AA19: 3 | AB19: =AA19*$B$19 -> 75
A20: =Hipótesis!$B$59 -> Alta e instalación Plan Vidriera | B20: =Hipótesis!C59 -> 60 | C20: =E20+G20+I20+K20+M20+O20+Q20+S20+U20+W20+Y20+AA20 -> 62 | D20: =B20*C20 -> 3720 | E20: 0 | F20: =E20*$B$20 -> 0 | G20: 1 | H20: =G20*$B$20 -> 60 | I20: 3 | J20: =I20*$B$20 -> 180 | K20: 4 | L20: =K20*$B$20 -> 240 | M20: 5 | N20: =M20*$B$20 -> 300 | O20: 5 | P20: =O20*$B$20 -> 300 | Q20: 6 | R20: =Q20*$B$20 -> 360 | S20: 7 | T20: =S20*$B$20 -> 420 | U20: 7 | V20: =U20*$B$20 -> 420 | W20: 8 | X20: =W20*$B$20 -> 480 | Y20: 8 | Z20: =Y20*$B$20 -> 480 | AA20: 8 | AB20: =AA20*$B$20 -> 480
A21: =Hipótesis!$B$60 -> Alta e instalación Plan Cadena | B21: =Hipótesis!C60 -> 250 | C21: =E21+G21+I21+K21+M21+O21+Q21+S21+U21+W21+Y21+AA21 -> 10 | D21: =B21*C21 -> 2500 | E21: 0 | F21: =E21*$B$21 -> 0 | G21: 0 | H21: =G21*$B$21 -> 0 | I21: 0 | J21: =I21*$B$21 -> 0 | K21: 0 | L21: =K21*$B$21 -> 0 | M21: 1 | N21: =M21*$B$21 -> 250 | O21: 1 | P21: =O21*$B$21 -> 250 | Q21: 1 | R21: =Q21*$B$21 -> 250 | S21: 1 | T21: =S21*$B$21 -> 250 | U21: 1 | V21: =U21*$B$21 -> 250 | W21: 1 | X21: =W21*$B$21 -> 250 | Y21: 1 | Z21: =Y21*$B$21 -> 250 | AA21: 3 | AB21: =AA21*$B$21 -> 750
A22: =Hipótesis!$B$61 -> Abono Plan Básico | B22: =Hipótesis!C61 -> 15 | C22: =E22+G22+I22+K22+M22+O22+Q22+S22+U22+W22+Y22+AA22 -> 148 | D22: =B22*C22 -> 2220 | E22: =E19 -> 0 | F22: =E22*$B$22 -> 0 | G22: =E22+G19 -> 1 | H22: =G22*$B$22 -> 15 | I22: =G22+I19 -> 2 | J22: =I22*$B$22 -> 30 | K22: =I22+K19 -> 4 | L22: =K22*$B$22 -> 60 | M22: =K22+M19 -> 6 | N22: =M22*$B$22 -> 90 | O22: =M22+O19 -> 9 | P22: =O22*$B$22 -> 135 | Q22: =O22+Q19 -> 12 | R22: =Q22*$B$22 -> 180 | S22: =Q22+S19 -> 15 | T22: =S22*$B$22 -> 225 | U22: =S22+U19 -> 19 | V22: =U22*$B$22 -> 285 | W22: =U22+W19 -> 23 | X22: =W22*$B$22 -> 345 | Y22: =W22+Y19 -> 27 | Z22: =Y22*$B$22 -> 405 | AA22: =Y22+AA19 -> 30 | AB22: =AA22*$B$22 -> 450
A23: =Hipótesis!$B$62 -> Abono Plan Vidriera | B23: =Hipótesis!C62 -> 29 | C23: =E23+G23+I23+K23+M23+O23+Q23+S23+U23+W23+Y23+AA23 -> 299 | D23: =B23*C23 -> 8671 | E23: =E20 -> 0 | F23: =E23*$B$23 -> 0 | G23: =E23+G20 -> 1 | H23: =G23*$B$23 -> 29 | I23: =G23+I20 -> 4 | J23: =I23*$B$23 -> 116 | K23: =I23+K20 -> 8 | L23: =K23*$B$23 -> 232 | M23: =K23+M20 -> 13 | N23: =M23*$B$23 -> 377 | O23: =M23+O20 -> 18 | P23: =O23*$B$23 -> 522 | Q23: =O23+Q20 -> 24 | R23: =Q23*$B$23 -> 696 | S23: =Q23+S20 -> 31 | T23: =S23*$B$23 -> 899 | U23: =S23+U20 -> 38 | V23: =U23*$B$23 -> 1102 | W23: =U23+W20 -> 46 | X23: =W23*$B$23 -> 1334 | Y23: =W23+Y20 -> 54 | Z23: =Y23*$B$23 -> 1566 | AA23: =Y23+AA20 -> 62 | AB23: =AA23*$B$23 -> 1798
A24: =Hipótesis!$B$63 -> Abono Plan Cadena | B24: =Hipótesis!C63 -> 79 | C24: =E24+G24+I24+K24+M24+O24+Q24+S24+U24+W24+Y24+AA24 -> 38 | D24: =B24*C24 -> 3002 | E24: =E21 -> 0 | F24: =E24*$B$24 -> 0 | G24: =E24+G21 -> 0 | H24: =G24*$B$24 -> 0 | I24: =G24+I21 -> 0 | J24: =I24*$B$24 -> 0 | K24: =I24+K21 -> 0 | L24: =K24*$B$24 -> 0 | M24: =K24+M21 -> 1 | N24: =M24*$B$24 -> 79 | O24: =M24+O21 -> 2 | P24: =O24*$B$24 -> 158 | Q24: =O24+Q21 -> 3 | R24: =Q24*$B$24 -> 237 | S24: =Q24+S21 -> 4 | T24: =S24*$B$24 -> 316 | U24: =S24+U21 -> 5 | V24: =U24*$B$24 -> 395 | W24: =U24+W21 -> 6 | X24: =W24*$B$24 -> 474 | Y24: =W24+Y21 -> 7 | Z24: =Y24*$B$24 -> 553 | AA24: =Y24+AA21 -> 10 | AB24: =AA24*$B$24 -> 790
A32: Ingreso Total | D32: =SUM(D19:D31) -> 20863 | F32: =SUM(F19:F31) -> 0 | H32: =SUM(H19:H31) -> 129 | J32: =SUM(J19:J31) -> 351 | L32: =SUM(L19:L31) -> 582 | N32: =SUM(N19:N31) -> 1146 | P32: =SUM(P19:P31) -> 1440 | R32: =SUM(R19:R31) -> 1798 | T32: =SUM(T19:T31) -> 2185 | V32: =SUM(V19:V31) -> 2552 | X32: =SUM(X19:X31) -> 2983 | Z32: =SUM(Z19:Z31) -> 3354 | AB32: =SUM(AB19:AB31) -> 4343
C33: =C19 -> 30 | E33: =E19 -> 0 | G33: =G19 -> 1 | I33: =I19 -> 1 | K33: =K19 -> 2 | M33: =M19 -> 2 | O33: =O19 -> 3 | Q33: =Q19 -> 3 | S33: =S19 -> 3 | U33: =U19 -> 4 | W33: =W19 -> 4 | Y33: =Y19 -> 4 | AA33: =AA19 -> 3
C34: =C20 -> 62 | E34: =E20 -> 0 | G34: =G20 -> 1 | I34: =I20 -> 3 | K34: =K20 -> 4 | M34: =M20 -> 5 | O34: =O20 -> 5 | Q34: =Q20 -> 6 | S34: =S20 -> 7 | U34: =U20 -> 7 | W34: =W20 -> 8 | Y34: =Y20 -> 8 | AA34: =AA20 -> 8
C35: =C21 -> 10 | E35: =E21 -> 0 | G35: =G21 -> 0 | I35: =I21 -> 0 | K35: =K21 -> 0 | M35: =M21 -> 1 | O35: =O21 -> 1 | Q35: =Q21 -> 1 | S35: =S21 -> 1 | U35: =U21 -> 1 | W35: =W21 -> 1 | Y35: =Y21 -> 1 | AA35: =AA21 -> 3
C36: =SUM(C22:C25) -> 485 | E36: =SUM(E22:E25) -> 0 | G36: =SUM(G22:G25) -> 2 | I36: =SUM(I22:I25) -> 6 | K36: =SUM(K22:K25) -> 12 | M36: =SUM(M22:M25) -> 20 | O36: =SUM(O22:O25) -> 29 | Q36: =SUM(Q22:Q25) -> 39 | S36: =SUM(S22:S25) -> 50 | U36: =SUM(U22:U25) -> 62 | W36: =SUM(W22:W25) -> 75 | Y36: =SUM(Y22:Y25) -> 88 | AA36: =SUM(AA22:AA25) -> 102
C37: =SUM(C26:C30) -> 0 | E37: =SUM(E26:E30) -> 0 | G37: =SUM(G26:G30) -> 0 | I37: =SUM(I26:I30) -> 0 | K37: =SUM(K26:K30) -> 0 | M37: =SUM(M26:M30) -> 0 | O37: =SUM(O26:O30) -> 0 | Q37: =SUM(Q26:Q30) -> 0 | S37: =SUM(S26:S30) -> 0 | U37: =SUM(U26:U30) -> 0 | W37: =SUM(W26:W30) -> 0 | Y37: =SUM(Y26:Y30) -> 0 | AA37: =SUM(AA26:AA30) -> 0
C38: =C31 -> 0 | E38: =E31 -> 0 | G38: =G31 -> 0 | I38: =I31 -> 0 | K38: =K31 -> 0 | M38: =M31 -> 0 | O38: =O31 -> 0 | Q38: =Q31 -> 0 | S38: =S31 -> 0 | U38: =U31 -> 0 | W38: =W31 -> 0 | Y38: =Y31 -> 0 | AA38: =AA31 -> 0
A40: Capacidad operativa Kick off - Año 2026
A41: Comentarios | B41: * Se arranca con el equipo fundador y un técnico. En julio se suma un segundo vendedor para sostener el ritmo de altas del segundo semestre.
A42: Concepto | C42: Año cero - Kick off | E42: Año 2026
C43: Cantidad | E43: Enero | G43: Febrero | I43: Marzo | K43: Abril | M43: Mayo | O43: Junio | Q43: Julio | S43: Agosto | U43: Septiembre | W43: Octubre | Y43: Noviembre | AA43: Diciembre
A44: RRHH | C44: Gerente general | E44: Sin cambios | G44: Sin cambios | I44: Sin cambios | K44: Sin cambios | M44: Sin cambios | O44: Sin cambios | Q44: Sin cambios | S44: Sin cambios | U44: Sin cambios | W44: Sin cambios | Y44: Sin cambios | AA44: Sin cambios
C45: Gerente de sistemas | E45: Sin cambios | G45: Sin cambios | I45: Sin cambios | K45: Sin cambios | M45: Sin cambios | O45: Sin cambios | Q45: Sin cambios | S45: Sin cambios | U45: Sin cambios | W45: Sin cambios | Y45: Sin cambios | AA45: Sin cambios
C46: Desarrollador | E46: Sin cambios | G46: Sin cambios | I46: Sin cambios | K46: Sin cambios | M46: Sin cambios | O46: Sin cambios | Q46: Sin cambios | S46: Sin cambios | U46: Sin cambios | W46: Sin cambios | Y46: Sin cambios | AA46: Sin cambios
C47: Técnico de instalación y soporte | E47: Sin cambios | G47: Sin cambios | I47: Sin cambios | K47: Sin cambios | M47: Sin cambios | O47: Sin cambios | Q47: Sin cambios | S47: Sin cambios | U47: Sin cambios | W47: Sin cambios | Y47: Sin cambios | AA47: Sin cambios
C48: Vendedor | E48: Sin cambios | G48: Sin cambios | I48: Sin cambios | K48: Sin cambios | M48: Sin cambios | O48: Sin cambios | Q48: Vendedor (+1) | S48: Sin cambios | U48: Sin cambios | W48: Sin cambios | Y48: Sin cambios | AA48: Sin cambios
A62: Infraestructura | C62: Oficina | E62: Oficina (+1 alquiler) | G62: Sin cambios | I62: Sin cambios | K62: Sin cambios | M62: Sin cambios | O62: Sin cambios | Q62: Sin cambios | S62: Sin cambios | U62: Sin cambios | W62: Sin cambios | Y62: Sin cambios | AA62: Sin cambios
C63: Notebooks | E63: Notebooks (+3) | G63: Sin cambios | I63: Sin cambios | K63: Sin cambios | M63: Sin cambios | O63: Sin cambios | Q63: Notebooks (+1) | S63: Sin cambios | U63: Sin cambios | W63: Sin cambios | Y63: Sin cambios | AA63: Sin cambios
C64: Escritorios | E64: Escritorios (+2) | G64: Sin cambios | I64: Sin cambios | K64: Sin cambios | M64: Sin cambios | O64: Sin cambios | Q64: Sin cambios | S64: Sin cambios | U64: Sin cambios | W64: Sin cambios | Y64: Sin cambios | AA64: Sin cambios
C65: Sillas de escritorio | E65: Sillas de escritorio (+4) | G65: Sin cambios | I65: Sin cambios | K65: Sin cambios | M65: Sin cambios | O65: Sin cambios | Q65: Sin cambios | S65: Sin cambios | U65: Sin cambios | W65: Sin cambios | Y65: Sin cambios | AA65: Sin cambios
C66: 0 | E66: Sin cambios | G66: Sin cambios | I66: Sin cambios | K66: Sin cambios | M66: Sin cambios | O66: Sin cambios | Q66: Sin cambios | S66: Sin cambios | U66: Sin cambios | W66: Sin cambios | Y66: Sin cambios | AA66: Sin cambios
C67: 0 | E67: Sin cambios | G67: Sin cambios | I67: Sin cambios | K67: Sin cambios | M67: Sin cambios | O67: Sin cambios | Q67: Sin cambios | S67: Sin cambios | U67: Sin cambios | W67: Sin cambios | Y67: Sin cambios | AA67: Sin cambios
C68: 0 | E68: Sin cambios | G68: Sin cambios | I68: Sin cambios | K68: Sin cambios | M68: Sin cambios | O68: Sin cambios | Q68: Sin cambios | S68: Sin cambios | U68: Sin cambios | W68: Sin cambios | Y68: Sin cambios | AA68: Sin cambios
A69: Capital de trabajo | C69: Sensores de vidriera | E69: Sensores de vidriera (+30) | G69: Sin cambios | I69: Sin cambios | K69: Sensores de vidriera (+30) | M69: Sin cambios | O69: Sin cambios | Q69: Sensores de vidriera (+30) | S69: Sin cambios | U69: Sin cambios | W69: Sensores de vidriera (+30) | Y69: Sin cambios | AA69: Sin cambios
...

Sheet Anexo capacidad operativa
C1: Anexo capacidad operativa
A3: Instalación y alta de los planes ShopMetrics | H3: Soporte mensual por plan | O3: Sueldo tecnico por hora: | P3: 6 | S3: Coste del kit de instalación | Y3: Coste del soporte mensual
A6: Cálculo de horas laborables de un empleado por mes
A7: Semanas por año | B7: 52 | C7: semanas
A8: Semanas de licencias varias al año | B8: 2 | C8: semanas
A9: Días festivos | B9: 14 | C9: días
A10: Días laborales totales | B10: =(B7-B8)*5 -B9 -> 236 | C10: días
A11: Jornada laboral | B11: 8 | C11: horas | T11: Alta remota: conexión con el punto de venta
A12: Horas laborables anuales por empleado | B12: =B10*B11 -> 1888 | C12: horas | T12: Visita al local: sensor de vidriera + contador de puerta
A13: Consideraremos en promedio: | B13: 1800 | C13: Horas laborables anuales / empleado | T13: Instalación en hasta cinco locales de una cadena
B14: 150 | C14: Horas laborables mensuales / empleado [HsLaboralesXMes]
A18: Alta e instalación Plan Básico | H18: Soporte mensual Plan Básico | S18: Kit Plan Básico | Y18: Soporte mensual Plan Básico
A19: N° de tarea | B19: Descripción | C19: Base horaria [BH] | D19: Cantidad requerida [Cant] | E19: Horas por tarea Fórmula = Cant * BH | H19: N° de tarea | I19: Descripción | J19: Base horaria [BH] | K19: Cantidad requerida [Cant] | L19: Horas por tarea Fórmula = Cant * BH | S19: Componente | U19: Cantidad | V19: Precio unitario | W19: Subtotal | Y19: Componente | AA19: Cantidad | AB19: Precio unitario | AC19: Subtotal
A20: 1 | B20: Contacto y coordinación | C20: 0.08 | D20: 1 | E20: =D20*C20 -> 0.08 | H20: 1 | I20: Monitoreo de ingesta | J20: 0.05 | K20: 1 | L20: =K20*J20 -> 0.05 | S20: Instalación (mano de obra) | U20: =$E$32 -> 0.5 | V20: =$P$3 -> 6 | W20: =V20*U20 -> 3 | Y20: Servicio técnico | AA20: =$L$32 -> 0.15 | AB20: =$P$3 -> 6 | AC20: =AB20*AA20 -> 0.9
A21: 2 | B21: Alta en la plataforma | C21: 0.08 | D21: 1 | E21: =D21*C21 -> 0.08 | H21: 2 | I21: Atención de consultas | J21: 0.07 | K21: 1 | L21: =K21*J21 -> 0.07
A22: 3 | B22: Conexión con el punto de venta | C22: 0.17 | D22: 1 | E22: =D22*C22 -> 0.17 | H22: 3 | I22: Reporte mensual | J22: 0.03 | K22: 1 | L22: =K22*J22 -> 0.03 | AB22: =V3 -> 0
A23: 4 | B23: Verificación de los datos | C23: 0.12 | D23: 1 | E23: =D23*C23 -> 0.12 | H23: 4 | L23: =K23*J23 -> 0
A24: 5 | B24: Capacitación remota | C24: 0.05 | D24: 1 | E24: =D24*C24 -> 0.05 | H24: 5 | L24: =K24*J24 -> 0
A25: 6 | E25: =D25*C25 -> 0 | H25: 6
A26: 7 | E26: =D26*C26 -> 0 | H26: 7
A27: 8 | E27: =D27*C27 -> 0 | H27: 8
A28: 9 | E28: =D28*C28 -> 0 | H28: 9 | S28: Total | W28: =SUM(W20:W25) -> 3 | Y28: Total | AC28: =SUM(AC20:AC25) -> 0.9
A29: 10 | E29: =D29*C29 -> 0 | H29: 10
A30: 11 | E30: =D30*C30 -> 0 | H30: 11
A31: 12 | E31: =D31*C31 -> 0 | H31: 12
A32: Comentarios: el alta del Plan Básico es remota, no requiere visita. | D32: Horas totales por servicio [HsTotalesXServicio] Fórmula = Σ Horas por tarea del servicio | E32: =SUM(E20:E31) -> 0.5 | F32: Coste por instalación | H32: Comentarios: soporte enteramente remoto. | K32: Horas totales por servicio [HsTotalesXServicio] | L32: =SUM(L20:L31) -> 0.15
D33: Capacidad operativa mensual por proyecto Fórmula = HsTotalesXSer / HsLaboralesXMes | E33: =E32/$B$14 -> 0.0033333333 | F33: =$P$3*E32 -> 3 | K33: Capacidad operativa mensual por proyecto | L33: =L32/$B$14 -> 0.001
A37: Alta e instalación Plan Vidriera | H37: Soporte mensual Plan Vidriera | S37: Kit Plan Vidriera | Y37: Soporte mensual Plan Vidriera
A38: N° de tarea | B38: Descripción | C38: Base horaria [BH] | D38: Cantidad requerida [Cant] | E38: Horas por tarea Fórmula = Cant * BH | H38: N° de tarea | I38: Descripción | J38: Base horaria [BH] | K38: Cantidad requerida [Cant] | L38: Horas por tarea Fórmula = Cant * BH | S38: Componente | U38: Cantidad | V38: Precio unitario | W38: Subtotal | Y38: Componente | AA38: Cantidad | AB38: Precio unitario | AC38: Subtotal
A39: 1 | B39: Coordinación y armado del kit | C39: 0.25 | D39: 1 | E39: =D39*C39 -> 0.25 | H39: 1 | I39: Monitoreo de ingesta | J39: 0.05 | K39: 1 | L39: =K39*J39 -> 0.05 | S39: Sensor de vidriera | U39: 1 | V39: 14 | W39: =V39*U39 -> 14 | Y39: Servicio técnico | AA39: =$L$51 -> 0.25 | AB39: =$P$3 -> 6 | AC39: =AB39*AA39 -> 1.5
A40: 2 | B40: Traslado al local | C40: 0.5 | D40: 1 | E40: =D40*C40 -> 0.5 | H40: 2 | I40: Control del sensor | J40: 0.07 | K40: 1 | L40: =K40*J40 -> 0.07 | S40: Contador de puerta | U40: 1 | V40: 9 | W40: =V40*U40 -> 9
A41: 3 | B41: Montaje del sensor de vidriera | C41: 0.75 | D41: 1 | E41: =D41*C41 -> 0.75 | H41: 3 | I41: Atención de consultas | J41: 0.08 | K41: 1 | L41: =K41*J41 -> 0.08 | S41: Gateway de conexión | U41: 1 | V41: 7 | W41: =V41*U41 -> 7
A42: 4 | B42: Instalación contador de puerta | C42: 0.5 | D42: 1 | E42: =D42*C42 -> 0.5 | H42: 4 | I42: Reporte mensual | J42: 0.05 | K42: 1 | L42: =K42*J42 -> 0.05 | S42: Kit de montaje | U42: 1 | V42: 4 | W42: =V42*U42 -> 4
A43: 5 | B43: Conexión con el punto de venta | C43: 0.25 | D43: 1 | E43: =D43*C43 -> 0.25 | H43: 5 | L43: =K43*J43 -> 0 | S43: Instalación (mano de obra) | U43: =$E$51 -> 3 | V43: =$P$3 -> 6 | W43: =V43*U43 -> 18
A44: 6 | B44: Prueba del embudo | C44: 0.5 | D44: 1 | E44: =D44*C44 -> 0.5 | H44: 6 | L44: =K44*J44 -> 0
A45: 7 | B45: Capacitación y cierre | C45: 0.25 | D45: 1 | E45: =D45*C45 -> 0.25 | H45: 7 | L45: 0
A46: 8 | E46: =D46*C46 -> 0 | H46: 8 | L46: 0
A47: 9 | E47: =D47*C47 -> 0 | H47: 9 | L47: 0 | S47: Total | W47: =SUM(W39:W44) -> 52 | Y47: Total | AC47: =SUM(AC39:AC44) -> 1.5
A48: 10 | E48: =D48*C48 -> 0 | H48: 10 | L48: 0
A49: 11 | E49: =D49*C49 -> 0 | H49: 11 | L49: 0
...

Sheet Mod. ingresos
E1: Modelo de ingresos
B7: Evolución de la participación
B8: 2026 | C8: 2027 | D8: 2028
B9: =Hipótesis!C24 -> 0.03 | C9: =Hipótesis!C25 -> 0.08 | D9: =Hipótesis!C26 -> 0.15
B10: =Hipótesis!D24 -> 48960 | C10: =Hipótesis!D25 -> 130560 | D10: =Hipótesis!D26 -> 244800
B15: Ingresos por servicios
B16: Servicio | C16: Ingresos 2026 | D16: Ingresos 2027 | E16: Ingresos 2028
B17: =Hipótesis!$B$58 -> Alta e instalación Plan Básico | C17: ='Proy. ventas'!D19 -> 750 | D17: ='Proy. ventas'!D82 -> 1275 | E17: ='Proy. ventas'!D144 -> 1775
B18: =Hipótesis!$B$59 -> Alta e instalación Plan Vidriera | C18: ='Proy. ventas'!D20 -> 3720 | D18: ='Proy. ventas'!D83 -> 6120 | E18: ='Proy. ventas'!D145 -> 8580
B19: =Hipótesis!$B$60 -> Alta e instalación Plan Cadena | C19: ='Proy. ventas'!D21 -> 2500 | D19: ='Proy. ventas'!D84 -> 4250 | E19: ='Proy. ventas'!D146 -> 6000
B20: =Hipótesis!$B$61 -> Abono Plan Básico | C20: ='Proy. ventas'!D22 -> 2220 | D20: ='Proy. ventas'!D85 -> 10140 | E20: ='Proy. ventas'!D147 -> 21585
B21: =Hipótesis!$B$62 -> Abono Plan Vidriera | C21: ='Proy. ventas'!D23 -> 8671 | D21: ='Proy. ventas'!D86 -> 40281 | E21: ='Proy. ventas'!D148 -> 84187
B22: =Hipótesis!$B$63 -> Abono Plan Cadena | C22: ='Proy. ventas'!D24 -> 3002 | D22: ='Proy. ventas'!D87 -> 17064 | E22: ='Proy. ventas'!D149 -> 37920
B30: TOTALES | C30: =SUM(C17:C29) -> 20863 | D30: =SUM(D17:D29) -> 79130 | E30: =SUM(E17:E29) -> 160047

Sheet Costos fijos
F1: Estructura de costos fijos
C3: Evolución de la participación | G3: Costos fijos - Totales
C4: 2026 | D4: 2027 | E4: 2028 | G4: 2026 | H4: 2027 | I4: 2028
C5: =Hipótesis!C24 -> 0.03 | D5: =Hipótesis!C25 -> 0.08 | E5: =Hipótesis!C26 -> 0.15 | G5: =P25 -> 25440 | H5: =P42 -> 33300 | I5: =P60 -> 37260
C6: =Hipótesis!D24 -> 48960 | D6: =Hipótesis!D25 -> 130560 | E6: =Hipótesis!D26 -> 244800
G7: Costos fijos de promoción - Totales
G8: 2026 | H8: 2027 | I8: 2028
G9: =SUM(P23:P24) -> 2400 | H9: =SUM(P40:P41) -> 3240 | I9: =SUM(P58:P59) -> 4320
B11: Costos fijos - Año 2026
B12: Rubro | C12: Concepto | D12: Enero | E12: Febrero | F12: Marzo | G12: Abril | H12: Mayo | I12: Junio | J12: Julio | K12: Agosto | L12: Septiembre | M12: Octubre | N12: Noviembre | O12: Diciembre | P12: Total anual | Q12: Observaciones
B13: Servicios | C13: Luz | D13: 45 | E13: 45 | F13: 45 | G13: 45 | H13: 45 | I13: 45 | J13: 45 | K13: 45 | L13: 45 | M13: 45 | N13: 45 | O13: 45 | P13: =SUM(D13:O13) -> 540
C14: Agua | D14: 15 | E14: 15 | F14: 15 | G14: 15 | H14: 15 | I14: 15 | J14: 15 | K14: 15 | L14: 15 | M14: 15 | N14: 15 | O14: 15 | P14: =SUM(D14:O14) -> 180
C15: Internet y telefonía fija | D15: 60 | E15: 60 | F15: 60 | G15: 60 | H15: 60 | I15: 60 | J15: 60 | K15: 60 | L15: 60 | M15: 60 | N15: 60 | O15: 60 | P15: =SUM(D15:O15) -> 720
C16: Telefonía móvil | D16: 30 | E16: 30 | F16: 30 | G16: 30 | H16: 30 | I16: 30 | J16: 30 | K16: 30 | L16: 30 | M16: 30 | N16: 30 | O16: 30 | P16: =SUM(D16:O16) -> 360 | Q16: Una línea por técnico y por vendedor; escala con la dotación.
C17: Infraestructura cloud base | D17: 250 | E17: 250 | F17: 250 | G17: 250 | H17: 250 | I17: 250 | J17: 250 | K17: 250 | L17: 250 | M17: 250 | N17: 250 | O17: 250 | P17: =SUM(D17:O17) -> 3000 | Q17: Capacidad mínima para operar con independencia de la cantidad de comercios activos.
C18: Licencias de software | D18: 120 | E18: 120 | F18: 120 | G18: 120 | H18: 120 | I18: 120 | J18: 120 | K18: 120 | L18: 120 | M18: 120 | N18: 120 | O18: 120 | P18: =SUM(D18:O18) -> 1440 | Q18: Herramientas de desarrollo, monitoreo y productividad.
B19: Alquiler | C19: Oficina | D19: 600 | E19: 600 | F19: 600 | G19: 600 | H19: 600 | I19: 600 | J19: 600 | K19: 600 | L19: 600 | M19: 600 | N19: 600 | O19: 600 | P19: =SUM(D19:O19) -> 7200 | Q19: En 2028 se amplía el espacio por el crecimiento de la dotación.
C20: Auditoría y certificación ISO 27001 | D20: 0 | E20: 0 | F20: 0 | G20: 0 | H20: 0 | I20: 0 | J20: 0 | K20: 0 | L20: 0 | M20: 0 | N20: 0 | O20: 0 | P20: =SUM(D20:O20) -> 0 | Q20: Implementación durante 2027 y mantenimiento desde 2028.
B21: Honorarios | C21: Estudio Contable Externo | D21: 400 | E21: 400 | F21: 400 | G21: 400 | H21: 400 | I21: 400 | J21: 400 | K21: 400 | L21: 400 | M21: 400 | N21: 400 | O21: 400 | P21: =SUM(D21:O21) -> 4800 | Q21: Escala por tramos con la cantidad de empleados.
C22: Agencia de marketing | D22: 400 | E22: 400 | F22: 400 | G22: 400 | H22: 400 | I22: 400 | J22: 400 | K22: 400 | L22: 400 | M22: 400 | N22: 400 | O22: 400 | P22: =SUM(D22:O22) -> 4800 | Q22: Abono mensual; la pauta se imputa aparte.
B23: Publicidad online | C23: Campañas base en Meta y Google | D23: 150 | E23: 150 | F23: 150 | G23: 150 | H23: 150 | I23: 150 | J23: 150 | K23: 150 | L23: 150 | M23: 150 | N23: 150 | O23: 150 | P23: =SUM(D23:O23) -> 1800 | Q23: Pauta base permanente; las campañas de captación intensiva van en costos variables.
C24: Sitio web, SEO local y WhatsApp Business | D24: 50 | E24: 50 | F24: 50 | G24: 50 | H24: 50 | I24: 50 | J24: 50 | K24: 50 | L24: 50 | M24: 50 | N24: 50 | O24: 50 | P24: =SUM(D24:O24) -> 600
B25: TOTAL | D25: =SUM(D13:D24) -> 2120 | E25: =SUM(E13:E24) -> 2120 | F25: =SUM(F13:F24) -> 2120 | G25: =SUM(G13:G24) -> 2120 | H25: =SUM(H13:H24) -> 2120 | I25: =SUM(I13:I24) -> 2120 | J25: =SUM(J13:J24) -> 2120 | K25: =SUM(K13:K24) -> 2120 | ... O25: =SUM(O13:O24) -> 2120 | P25: =SUM(D25:O25) -> 25440
B28: Costos fijos - Año 2027
B29: Rubro | C29: Concepto | D29: Enero | E29: Febrero | F29: Marzo | G29: Abril | H29: Mayo | I29: Junio | J29: Julio | K29: Agosto | L29: Septiembre | M29: Octubre | N29: Noviembre | O29: Diciembre | P29: Total anual | Q29: Observaciones
B30: Servicios | C30: Luz | D30: 45 | E30: 45 | F30: 45 | G30: 45 | H30: 45 | I30: 45 | J30: 45 | K30: 45 | L30: 45 | M30: 45 | N30: 45 | O30: 45 | P30: =SUM(D30:O30) -> 540
C31: Agua | D31: 15 | E31: 15 | F31: 15 | G31: 15 | H31: 15 | I31: 15 | J31: 15 | K31: 15 | L31: 15 | M31: 15 | N31: 15 | O31: 15 | P31: =SUM(D31:O31) -> 180
C32: Internet y telefonía fija | D32: 60 | E32: 60 | F32: 60 | G32: 60 | H32: 60 | I32: 60 | J32: 60 | K32: 60 | L32: 60 | M32: 60 | N32: 60 | O32: 60 | P32: =SUM(D32:O32) -> 720
C33: Telefonía móvil | D33: 45 | E33: 45 | F33: 45 | G33: 45 | H33: 45 | I33: 45 | J33: 45 | K33: 45 | L33: 45 | M33: 45 | N33: 45 | O33: 45 | P33: =SUM(D33:O33) -> 540 | Q33: Una línea por técnico y por vendedor; escala con la dotación.
C34: Infraestructura cloud base | D34: 350 | E34: 350 | F34: 350 | G34: 350 | H34: 350 | I34: 350 | J34: 350 | K34: 350 | L34: 350 | M34: 350 | N34: 350 | O34: 350 | P34: =SUM(D34:O34) -> 4200 | Q34: Capacidad mínima para operar con independencia de la cantidad de comercios activos.
C35: Licencias de software | D35: 140 | E35: 140 | F35: 140 | G35: 140 | H35: 140 | I35: 140 | J35: 140 | K35: 140 | L35: 140 | M35: 140 | N35: 140 | O35: 140 | P35: =SUM(D35:O35) -> 1680 | Q35: Herramientas de desarrollo, monitoreo y productividad.
B36: Alquiler | C36: Oficina | D36: 600 | E36: 600 | F36: 600 | G36: 600 | H36: 600 | I36: 600 | J36: 600 | K36: 600 | L36: 600 | M36: 600 | N36: 600 | O36: 600 | P36: =SUM(D36:O36) -> 7200 | Q36: En 2028 se amplía el espacio por el crecimiento de la dotación.
C37: Auditoría y certificación ISO 27001 | D37: 400 | E37: 400 | F37: 400 | G37: 400 | H37: 400 | I37: 400 | J37: 400 | K37: 400 | L37: 400 | M37: 400 | N37: 400 | O37: 400 | P37: =SUM(D37:O37) -> 4800 | Q37: Implementación durante 2027 y mantenimiento desde 2028.
B38: Honorarios | C38: Estudio Contable Externo | D38: 450 | E38: 450 | F38: 450 | G38: 450 | H38: 450 | I38: 450 | J38: 450 | K38: 450 | L38: 450 | M38: 450 | N38: 450 | O38: 450 | P38: =SUM(D38:O38) -> 5400 | Q38: Escala por tramos con la cantidad de empleados.
C39: Agencia de marketing | D39: 400 | E39: 400 | F39: 400 | G39: 400 | H39: 400 | I39: 400 | J39: 400 | K39: 400 | L39: 400 | M39: 400 | N39: 400 | O39: 400 | P39: =SUM(D39:O39) -> 4800 | Q39: Abono mensual; la pauta se imputa aparte.
B40: Publicidad online | C40: Campañas base en Meta y Google | D40: 220 | E40: 220 | F40: 220 | G40: 220 | H40: 220 | I40: 220 | J40: 220 | K40: 220 | L40: 220 | M40: 220 | N40: 220 | O40: 220 | P40: =SUM(D40:O40) -> 2640 | Q40: Pauta base permanente; las campañas de captación intensiva van en costos variables.
C41: Sitio web, SEO local y WhatsApp Business | D41: 50 | E41: 50 | F41: 50 | G41: 50 | H41: 50 | I41: 50 | J41: 50 | K41: 50 | L41: 50 | M41: 50 | N41: 50 | O41: 50 | P41: =SUM(D41:O41) -> 600
B42: TOTAL | D42: =SUM(D30:D41) -> 2775 | E42: =SUM(E30:E41) -> 2775 | F42: =SUM(F30:F41) -> 2775 | G42: =SUM(G30:G41) -> 2775 | H42: =SUM(H30:H41) -> 2775 | I42: =SUM(I30:I41) -> 2775 | J42: =SUM(J30:J41) -> 2775 | K42: =SUM(K30:K41) -> 2775 | ... O42: =SUM(O30:O41) -> 2775 | P42: =SUM(D42:O42) -> 33300
B46: Costos fijos - Año 2028
B47: Rubro | C47: Concepto | D47: Enero | E47: Febrero | F47: Marzo | G47: Abril | H47: Mayo | I47: Junio | J47: Julio | K47: Agosto | L47: Septiembre | M47: Octubre | N47: Noviembre | O47: Diciembre | P47: Total anual | Q47: Observaciones
...

Sheet Costos variables
F1: Estructura de costos variables
B4: Evolución de la participación | H4: Costos variables - Totales
B5: 2026 | C5: 2027 | D5: 2028 | H5: 2026 | I5: 2027 | J5: 2028
B6: =Hipótesis!C24 -> 0.03 | C6: =Hipótesis!C25 -> 0.08 | D6: =Hipótesis!C26 -> 0.15 | H6: =AB32 -> 5402 | I6: =AB55 -> 11065.9 | J6: =AB78 -> 17774.3
B7: =Hipótesis!D24 -> 48960 | C7: =Hipótesis!D25 -> 130560 | D7: =Hipótesis!D26 -> 244800
H8: Costos de promoción variables - Totales
H9: 2026 | I9: 2027 | J9: 2028
H10: =SUM(AB21:AB24) -> 2401 | I10: =SUM(AB44:AB47) -> 4013.5 | J10: =SUM(AB67:AB70) -> 5616.5
B12: Costos variables - Año 2026
A13: Rubro | B13: Descripción | C13: Costo unitario | D13: Enero | F13: Febrero | H13: Marzo | J13: Abril | L13: Mayo | N13: Junio | P13: Julio | R13: Agosto | T13: Septiembre | V13: Octubre | X13: Noviembre | Z13: Diciembre | AB13: Total anual
D14: Cant. | E14: Costo | F14: Cant. | G14: Costo | H14: Cant. | I14: Costo | J14: Cant. | K14: Costo | L14: Cant. | M14: Costo | N14: Cant. | O14: Costo | P14: Cant. | Q14: Costo | R14: Cant. | S14: Costo | T14: Cant. | U14: Costo | V14: Cant. | W14: Costo | X14: Cant. | Y14: Costo | Z14: Cant. | AA14: Costo
A15: Operación | B15: Comisión del vendedor por alta concretada | C15: 15 | D15: ='Proy. ventas'!E19+'Proy. ventas'!E20+'Proy. ventas'!E21 -> 0 | E15: =D15*$C15 -> 0 | F15: ='Proy. ventas'!G19+'Proy. ventas'!G20+'Proy. ventas'!G21 -> 2 | G15: =F15*$C15 -> 30 | H15: ='Proy. ventas'!I19+'Proy. ventas'!I20+'Proy. ventas'!I21 -> 4 | I15: =H15*$C15 -> 60 | J15: ='Proy. ventas'!K19+'Proy. ventas'!K20+'Proy. ventas'!K21 -> 6 | K15: =J15*$C15 -> 90 | L15: ='Proy. ventas'!M19+'Proy. ventas'!M20+'Proy. ventas'!M21 -> 8 | M15: =L15*$C15 -> 120 | N15: ='Proy. ventas'!O19+'Proy. ventas'!O20+'Proy. ventas'!O21 -> 9 | O15: =N15*$C15 -> 135 | P15: ='Proy. ventas'!Q19+'Proy. ventas'!Q20+'Proy. ventas'!Q21 -> 10 | Q15: =P15*$C15 -> 150 | R15: ='Proy. ventas'!S19+'Proy. ventas'!S20+'Proy. ventas'!S21 -> 11 | S15: =R15*$C15 -> 165 | T15: ='Proy. ventas'!U19+'Proy. ventas'!U20+'Proy. ventas'!U21 -> 12 | U15: =T15*$C15 -> 180 | V15: ='Proy. ventas'!W19+'Proy. ventas'!W20+'Proy. ventas'!W21 -> 13 | W15: =V15*$C15 -> 195 | X15: ='Proy. ventas'!Y19+'Proy. ventas'!Y20+'Proy. ventas'!Y21 -> 13 | Y15: =X15*$C15 -> 195 | Z15: ='Proy. ventas'!AA19+'Proy. ventas'!AA20+'Proy. ventas'!AA21 -> 14 | AA15: =Z15*$C15 -> 210 | AB15: =E15+G15+I15+K15+M15+O15+Q15+S15+U15+W15+Y15+AA15 -> 1530
B16: Movilidad y viáticos de instalación | C16: 5 | D16: ='Proy. ventas'!E20+'Proy. ventas'!E21 -> 0 | E16: =D16*$C16 -> 0 | F16: ='Proy. ventas'!G20+'Proy. ventas'!G21 -> 1 | G16: =F16*$C16 -> 5 | H16: ='Proy. ventas'!I20+'Proy. ventas'!I21 -> 3 | I16: =H16*$C16 -> 15 | J16: ='Proy. ventas'!K20+'Proy. ventas'!K21 -> 4 | K16: =J16*$C16 -> 20 | L16: ='Proy. ventas'!M20+'Proy. ventas'!M21 -> 6 | M16: =L16*$C16 -> 30 | N16: ='Proy. ventas'!O20+'Proy. ventas'!O21 -> 6 | O16: =N16*$C16 -> 30 | P16: ='Proy. ventas'!Q20+'Proy. ventas'!Q21 -> 7 | Q16: =P16*$C16 -> 35 | R16: ='Proy. ventas'!S20+'Proy. ventas'!S21 -> 8 | S16: =R16*$C16 -> 40 | T16: ='Proy. ventas'!U20+'Proy. ventas'!U21 -> 8 | U16: =T16*$C16 -> 40 | V16: ='Proy. ventas'!W20+'Proy. ventas'!W21 -> 9 | W16: =V16*$C16 -> 45 | X16: ='Proy. ventas'!Y20+'Proy. ventas'!Y21 -> 9 | Y16: =X16*$C16 -> 45 | Z16: ='Proy. ventas'!AA20+'Proy. ventas'!AA21 -> 11 | AA16: =Z16*$C16 -> 55 | AB16: =E16+G16+I16+K16+M16+O16+Q16+S16+U16+W16+Y16+AA16 -> 360
B17: Consumo cloud por comercio activo | C17: 0.35 | D17: ='Proy. ventas'!E22+'Proy. ventas'!E23+'Proy. ventas'!E24 -> 0 | E17: =D17*$C17 -> 0 | F17: ='Proy. ventas'!G22+'Proy. ventas'!G23+'Proy. ventas'!G24 -> 2 | G17: =F17*$C17 -> 0.7 | H17: ='Proy. ventas'!I22+'Proy. ventas'!I23+'Proy. ventas'!I24 -> 6 | I17: =H17*$C17 -> 2.1 | J17: ='Proy. ventas'!K22+'Proy. ventas'!K23+'Proy. ventas'!K24 -> 12 | K17: =J17*$C17 -> 4.2 | L17: ='Proy. ventas'!M22+'Proy. ventas'!M23+'Proy. ventas'!M24 -> 20 | M17: =L17*$C17 -> 7 | N17: ='Proy. ventas'!O22+'Proy. ventas'!O23+'Proy. ventas'!O24 -> 29 | O17: =N17*$C17 -> 10.15 | P17: ='Proy. ventas'!Q22+'Proy. ventas'!Q23+'Proy. ventas'!Q24 -> 39 | Q17: =P17*$C17 -> 13.65 | R17: ='Proy. ventas'!S22+'Proy. ventas'!S23+'Proy. ventas'!S24 -> 50 | S17: =R17*$C17 -> 17.5 | T17: ='Proy. ventas'!U22+'Proy. ventas'!U23+'Proy. ventas'!U24 -> 62 | U17: =T17*$C17 -> 21.7 | V17: ='Proy. ventas'!W22+'Proy. ventas'!W23+'Proy. ventas'!W24 -> 75 | W17: =V17*$C17 -> 26.25 | X17: ='Proy. ventas'!Y22+'Proy. ventas'!Y23+'Proy. ventas'!Y24 -> 88 | Y17: =X17*$C17 -> 30.8 | Z17: ='Proy. ventas'!AA22+'Proy. ventas'!AA23+'Proy. ventas'!AA24 -> 102 | AA17: =Z17*$C17 -> 35.7 | AB17: =E17+G17+I17+K17+M17+O17+Q17+S17+U17+W17+Y17+AA17 -> 169.75
B18: Gateway de notificaciones | C18: 0.15 | D18: ='Proy. ventas'!E22+'Proy. ventas'!E23+'Proy. ventas'!E24 -> 0 | E18: =D18*$C18 -> 0 | F18: ='Proy. ventas'!G22+'Proy. ventas'!G23+'Proy. ventas'!G24 -> 2 | G18: =F18*$C18 -> 0.3 | H18: ='Proy. ventas'!I22+'Proy. ventas'!I23+'Proy. ventas'!I24 -> 6 | I18: =H18*$C18 -> 0.9 | J18: ='Proy. ventas'!K22+'Proy. ventas'!K23+'Proy. ventas'!K24 -> 12 | K18: =J18*$C18 -> 1.8 | L18: ='Proy. ventas'!M22+'Proy. ventas'!M23+'Proy. ventas'!M24 -> 20 | M18: =L18*$C18 -> 3 | N18: ='Proy. ventas'!O22+'Proy. ventas'!O23+'Proy. ventas'!O24 -> 29 | O18: =N18*$C18 -> 4.35 | P18: ='Proy. ventas'!Q22+'Proy. ventas'!Q23+'Proy. ventas'!Q24 -> 39 | Q18: =P18*$C18 -> 5.85 | R18: ='Proy. ventas'!S22+'Proy. ventas'!S23+'Proy. ventas'!S24 -> 50 | S18: =R18*$C18 -> 7.5 | T18: ='Proy. ventas'!U22+'Proy. ventas'!U23+'Proy. ventas'!U24 -> 62 | U18: =T18*$C18 -> 9.3 | V18: ='Proy. ventas'!W22+'Proy. ventas'!W23+'Proy. ventas'!W24 -> 75 | W18: =V18*$C18 -> 11.25 | X18: ='Proy. ventas'!Y22+'Proy. ventas'!Y23+'Proy. ventas'!Y24 -> 88 | Y18: =X18*$C18 -> 13.2 | Z18: ='Proy. ventas'!AA22+'Proy. ventas'!AA23+'Proy. ventas'!AA24 -> 102 | AA18: =Z18*$C18 -> 15.3 | AB18: =E18+G18+I18+K18+M18+O18+Q18+S18+U18+W18+Y18+AA18 -> 72.75
B19: Comisiones de medios de pago | C19: 0.9 | D19: ='Proy. ventas'!E22+'Proy. ventas'!E23+'Proy. ventas'!E24 -> 0 | E19: =D19*$C19 -> 0 | F19: ='Proy. ventas'!G22+'Proy. ventas'!G23+'Proy. ventas'!G24 -> 2 | G19: =F19*$C19 -> 1.8 | H19: ='Proy. ventas'!I22+'Proy. ventas'!I23+'Proy. ventas'!I24 -> 6 | I19: =H19*$C19 -> 5.4 | J19: ='Proy. ventas'!K22+'Proy. ventas'!K23+'Proy. ventas'!K24 -> 12 | K19: =J19*$C19 -> 10.8 | L19: ='Proy. ventas'!M22+'Proy. ventas'!M23+'Proy. ventas'!M24 -> 20 | M19: =L19*$C19 -> 18 | N19: ='Proy. ventas'!O22+'Proy. ventas'!O23+'Proy. ventas'!O24 -> 29 | O19: =N19*$C19 -> 26.1 | P19: ='Proy. ventas'!Q22+'Proy. ventas'!Q23+'Proy. ventas'!Q24 -> 39 | Q19: =P19*$C19 -> 35.1 | R19: ='Proy. ventas'!S22+'Proy. ventas'!S23+'Proy. ventas'!S24 -> 50 | S19: =R19*$C19 -> 45 | T19: ='Proy. ventas'!U22+'Proy. ventas'!U23+'Proy. ventas'!U24 -> 62 | U19: =T19*$C19 -> 55.8 | V19: ='Proy. ventas'!W22+'Proy. ventas'!W23+'Proy. ventas'!W24 -> 75 | W19: =V19*$C19 -> 67.5 | X19: ='Proy. ventas'!Y22+'Proy. ventas'!Y23+'Proy. ventas'!Y24 -> 88 | Y19: =X19*$C19 -> 79.2 | Z19: ='Proy. ventas'!AA22+'Proy. ventas'!AA23+'Proy. ventas'!AA24 -> 102 | AA19: =Z19*$C19 -> 91.8 | AB19: =E19+G19+I19+K19+M19+O19+Q19+S19+U19+W19+Y19+AA19 -> 436.5
B20: Reposición de equipamiento no recuperado | C20: 6 | D20: ='Proy. ventas'!E20+'Proy. ventas'!E21 -> 0 | E20: =D20*$C20 -> 0 | F20: ='Proy. ventas'!G20+'Proy. ventas'!G21 -> 1 | G20: =F20*$C20 -> 6 | H20: ='Proy. ventas'!I20+'Proy. ventas'!I21 -> 3 | I20: =H20*$C20 -> 18 | J20: ='Proy. ventas'!K20+'Proy. ventas'!K21 -> 4 | K20: =J20*$C20 -> 24 | L20: ='Proy. ventas'!M20+'Proy. ventas'!M21 -> 6 | M20: =L20*$C20 -> 36 | N20: ='Proy. ventas'!O20+'Proy. ventas'!O21 -> 6 | O20: =N20*$C20 -> 36 | P20: ='Proy. ventas'!Q20+'Proy. ventas'!Q21 -> 7 | Q20: =P20*$C20 -> 42 | R20: ='Proy. ventas'!S20+'Proy. ventas'!S21 -> 8 | S20: =R20*$C20 -> 48 | T20: ='Proy. ventas'!U20+'Proy. ventas'!U21 -> 8 | U20: =T20*$C20 -> 48 | V20: ='Proy. ventas'!W20+'Proy. ventas'!W21 -> 9 | W20: =V20*$C20 -> 54 | X20: ='Proy. ventas'!Y20+'Proy. ventas'!Y21 -> 9 | Y20: =X20*$C20 -> 54 | Z20: ='Proy. ventas'!AA20+'Proy. ventas'!AA21 -> 11 | AA20: =Z20*$C20 -> 66 | AB20: =E20+G20+I20+K20+M20+O20+Q20+S20+U20+W20+Y20+AA20 -> 432
A21: Promoción | B21: Bonificación del alta - Plan Básico | C21: =Hipótesis!$C$58*0.3 -> 7.5 | D21: ='Proy. ventas'!E19 -> 0 | E21: =D21*$C21 -> 0 | F21: ='Proy. ventas'!G19 -> 1 | G21: =F21*$C21 -> 7.5 | H21: ='Proy. ventas'!I19 -> 1 | I21: =H21*$C21 -> 7.5 | J21: ='Proy. ventas'!K19 -> 2 | K21: =J21*$C21 -> 15 | L21: ='Proy. ventas'!M19 -> 2 | M21: =L21*$C21 -> 15 | N21: ='Proy. ventas'!O19 -> 3 | O21: =N21*$C21 -> 22.5 | P21: ='Proy. ventas'!Q19 -> 3 | Q21: =P21*$C21 -> 22.5 | R21: ='Proy. ventas'!S19 -> 3 | S21: =R21*$C21 -> 22.5 | T21: ='Proy. ventas'!U19 -> 4 | U21: =T21*$C21 -> 30 | V21: ='Proy. ventas'!W19 -> 4 | W21: =V21*$C21 -> 30 | X21: ='Proy. ventas'!Y19 -> 4 | Y21: =X21*$C21 -> 30 | Z21: ='Proy. ventas'!AA19 -> 3 | AA21: =Z21*$C21 -> 22.5 | AB21: =E21+G21+I21+K21+M21+O21+Q21+S21+U21+W21+Y21+AA21 -> 225
B22: Bonificación del alta - Plan Vidriera | C22: =Hipótesis!$C$59*0.3 -> 18 | D22: ='Proy. ventas'!E20 -> 0 | E22: =D22*$C22 -> 0 | F22: ='Proy. ventas'!G20 -> 1 | G22: =F22*$C22 -> 18 | H22: ='Proy. ventas'!I20 -> 3 | I22: =H22*$C22 -> 54 | J22: ='Proy. ventas'!K20 -> 4 | K22: =J22*$C22 -> 72 | L22: ='Proy. ventas'!M20 -> 5 | M22: =L22*$C22 -> 90 | N22: ='Proy. ventas'!O20 -> 5 | O22: =N22*$C22 -> 90 | P22: ='Proy. ventas'!Q20 -> 6 | Q22: =P22*$C22 -> 108 | R22: ='Proy. ventas'!S20 -> 7 | S22: =R22*$C22 -> 126 | T22: ='Proy. ventas'!U20 -> 7 | U22: =T22*$C22 -> 126 | V22: ='Proy. ventas'!W20 -> 8 | W22: =V22*$C22 -> 144 | X22: ='Proy. ventas'!Y20 -> 8 | Y22: =X22*$C22 -> 144 | Z22: ='Proy. ventas'!AA20 -> 8 | AA22: =Z22*$C22 -> 144 | AB22: =E22+G22+I22+K22+M22+O22+Q22+S22+U22+W22+Y22+AA22 -> 1116
B23: Bonificación del alta - Plan Cadena | C23: =Hipótesis!$C$60*0.3 -> 75 | D23: ='Proy. ventas'!E21 -> 0 | E23: =D23*$C23 -> 0 | F23: ='Proy. ventas'!G21 -> 0 | G23: =F23*$C23 -> 0 | H23: ='Proy. ventas'!I21 -> 0 | I23: =H23*$C23 -> 0 | J23: ='Proy. ventas'!K21 -> 0 | K23: =J23*$C23 -> 0 | L23: ='Proy. ventas'!M21 -> 1 | M23: =L23*$C23 -> 75 | N23: ='Proy. ventas'!O21 -> 1 | O23: =N23*$C23 -> 75 | P23: ='Proy. ventas'!Q21 -> 1 | Q23: =P23*$C23 -> 75 | R23: ='Proy. ventas'!S21 -> 1 | S23: =R23*$C23 -> 75 | T23: ='Proy. ventas'!U21 -> 1 | U23: =T23*$C23 -> 75 | V23: ='Proy. ventas'!W21 -> 1 | W23: =V23*$C23 -> 75 | X23: ='Proy. ventas'!Y21 -> 1 | Y23: =X23*$C23 -> 75 | Z23: ='Proy. ventas'!AA21 -> 3 | AA23: =Z23*$C23 -> 225 | AB23: =E23+G23+I23+K23+M23+O23+Q23+S23+U23+W23+Y23+AA23 -> 750
B24: Incentivo del programa de referidos | C24: 10 | D24: =ROUND(('Proy. ventas'!E19+'Proy. ventas'!E20+'Proy. ventas'!E21)*0.3,0) -> 0 | E24: =D24*$C24 -> 0 | F24: =ROUND(('Proy. ventas'!G19+'Proy. ventas'!G20+'Proy. ventas'!G21)*0.3,0) -> 1 | G24: =F24*$C24 -> 10 | H24: =ROUND(('Proy. ventas'!I19+'Proy. ventas'!I20+'Proy. ventas'!I21)*0.3,0) -> 1 | I24: =H24*$C24 -> 10 | J24: =ROUND(('Proy. ventas'!K19+'Proy. ventas'!K20+'Proy. ventas'!K21)*0.3,0) -> 2 | K24: =J24*$C24 -> 20 | L24: =ROUND(('Proy. ventas'!M19+'Proy. ventas'!M20+'Proy. ventas'!M21)*0.3,0) -> 2 | M24: =L24*$C24 -> 20 | N24: =ROUND(('Proy. ventas'!O19+'Proy. ventas'!O20+'Proy. ventas'!O21)*0.3,0) -> 3 | O24: =N24*$C24 -> 30 | P24: =ROUND(('Proy. ventas'!Q19+'Proy. ventas'!Q20+'Proy. ventas'!Q21)*0.3,0) -> 3 | Q24: =P24*$C24 -> 30 | R24: =ROUND(('Proy. ventas'!S19+'Proy. ventas'!S20+'Proy. ventas'!S21)*0.3,0) -> 3 | S24: =R24*$C24 -> 30 | T24: =ROUND(('Proy. ventas'!U19+'Proy. ventas'!U20+'Proy. ventas'!U21)*0.3,0) -> 4 | U24: =T24*$C24 -> 40 | V24: =ROUND(('Proy. ventas'!W19+'Proy. ventas'!W20+'Proy. ventas'!W21)*0.3,0) -> 4 | W24: =V24*$C24 -> 40 | X24: =ROUND(('Proy. ventas'!Y19+'Proy. ventas'!Y20+'Proy. ventas'!Y21)*0.3,0) -> 4 | Y24: =X24*$C24 -> 40 | Z24: =ROUND(('Proy. ventas'!AA19+'Proy. ventas'!AA20+'Proy. ventas'!AA21)*0.3,0) -> 4 | AA24: =Z24*$C24 -> 40 | AB24: =E24+G24+I24+K24+M24+O24+Q24+S24+U24+W24+Y24+AA24 -> 310
B32: TOTAL | E32: =SUM(E15:E24) -> 0 | G32: =SUM(G15:G24) -> 79.3 | I32: =SUM(I15:I24) -> 172.9 | K32: =SUM(K15:K24) -> 257.8 | M32: =SUM(M15:M24) -> 414 | O32: =SUM(O15:O24) -> 459.1 | Q32: =SUM(Q15:Q24) -> 517.1 | S32: =SUM(S15:S24) -> 576.5 | U32: =SUM(U15:U24) -> 625.8 | W32: =SUM(W15:W24) -> 688 | Y32: =SUM(Y15:Y24) -> 706.2 | AA32: =SUM(AA15:AA24) -> 905.3 | AB32: =SUM(AB15:AB24) -> 5402
B35: Costos variables - Año 2027
A36: Rubro | B36: Descripción | C36: Costo unitario | D36: Enero | F36: Febrero | H36: Marzo | J36: Abril | L36: Mayo | N36: Junio | P36: Julio | R36: Agosto | T36: Septiembre | V36: Octubre | X36: Noviembre | Z36: Diciembre | AB36: Total anual
D37: Cant. | E37: Costo | F37: Cant. | G37: Costo | H37: Cant. | I37: Costo | J37: Cant. | K37: Costo | L37: Cant. | M37: Costo | N37: Cant. | O37: Costo | P37: Cant. | Q37: Costo | R37: Cant. | S37: Costo | T37: Cant. | U37: Costo | V37: Cant. | W37: Costo | X37: Cant. | Y37: Costo | Z37: Cant. | AA37: Costo
A38: Operación | B38: Comisión del vendedor por alta concretada | C38: 15 | D38: ='Proy. ventas'!E82+'Proy. ventas'!E83+'Proy. ventas'!E84 -> 13 | E38: =D38*$C38 -> 195 | F38: ='Proy. ventas'!G82+'Proy. ventas'!G83+'Proy. ventas'!G84 -> 13 | G38: =F38*$C38 -> 195 | H38: ='Proy. ventas'!I82+'Proy. ventas'!I83+'Proy. ventas'!I84 -> 13 | I38: =H38*$C38 -> 195 | J38: ='Proy. ventas'!K82+'Proy. ventas'!K83+'Proy. ventas'!K84 -> 13 | K38: =J38*$C38 -> 195 | L38: ='Proy. ventas'!M82+'Proy. ventas'!M83+'Proy. ventas'!M84 -> 13 | M38: =L38*$C38 -> 195 | N38: ='Proy. ventas'!O82+'Proy. ventas'!O83+'Proy. ventas'!O84 -> 14 | O38: =N38*$C38 -> 210 | P38: ='Proy. ventas'!Q82+'Proy. ventas'!Q83+'Proy. ventas'!Q84 -> 14 | Q38: =P38*$C38 -> 210 | R38: ='Proy. ventas'!S82+'Proy. ventas'!S83+'Proy. ventas'!S84 -> 15 | S38: =R38*$C38 -> 225 | T38: ='Proy. ventas'!U82+'Proy. ventas'!U83+'Proy. ventas'!U84 -> 14 | U38: =T38*$C38 -> 210 | V38: ='Proy. ventas'!W82+'Proy. ventas'!W83+'Proy. ventas'!W84 -> 15 | W38: =V38*$C38 -> 225 | X38: ='Proy. ventas'!Y82+'Proy. ventas'!Y83+'Proy. ventas'!Y84 -> 16 | Y38: =X38*$C38 -> 240 | Z38: ='Proy. ventas'!AA82+'Proy. ventas'!AA83+'Proy. ventas'!AA84 -> 17 | AA38: =Z38*$C38 -> 255 | AB38: =E38+G38+I38+K38+M38+O38+Q38+S38+U38+W38+Y38+AA38 -> 2550
B39: Movilidad y viáticos de instalación | C39: 5 | D39: ='Proy. ventas'!E83+'Proy. ventas'!E84 -> 9 | E39: =D39*$C39 -> 45 | F39: ='Proy. ventas'!G83+'Proy. ventas'!G84 -> 9 | G39: =F39*$C39 -> 45 | H39: ='Proy. ventas'!I83+'Proy. ventas'!I84 -> 9 | I39: =H39*$C39 -> 45 | J39: ='Proy. ventas'!K83+'Proy. ventas'!K84 -> 9 | K39: =J39*$C39 -> 45 | L39: ='Proy. ventas'!M83+'Proy. ventas'!M84 -> 9 | M39: =L39*$C39 -> 45 | N39: ='Proy. ventas'!O83+'Proy. ventas'!O84 -> 10 | O39: =N39*$C39 -> 50 | P39: ='Proy. ventas'!Q83+'Proy. ventas'!Q84 -> 10 | Q39: =P39*$C39 -> 50 | R39: ='Proy. ventas'!S83+'Proy. ventas'!S84 -> 11 | S39: =R39*$C39 -> 55 | T39: ='Proy. ventas'!U83+'Proy. ventas'!U84 -> 10 | U39: =T39*$C39 -> 50 | V39: ='Proy. ventas'!W83+'Proy. ventas'!W84 -> 11 | W39: =V39*$C39 -> 55 | X39: ='Proy. ventas'!Y83+'Proy. ventas'!Y84 -> 11 | Y39: =X39*$C39 -> 55 | Z39: ='Proy. ventas'!AA83+'Proy. ventas'!AA84 -> 11 | AA39: =Z39*$C39 -> 55 | AB39: =E39+G39+I39+K39+M39+O39+Q39+S39+U39+W39+Y39+AA39 -> 595
B40: Consumo cloud por comercio activo | C40: 0.35 | D40: ='Proy. ventas'!E85+'Proy. ventas'!E86+'Proy. ventas'!E87 -> 115 | E40: =D40*$C40 -> 40.25 | F40: ='Proy. ventas'!G85+'Proy. ventas'!G86+'Proy. ventas'!G87 -> 128 | G40: =F40*$C40 -> 44.8 | H40: ='Proy. ventas'!I85+'Proy. ventas'!I86+'Proy. ventas'!I87 -> 141 | I40: =H40*$C40 -> 49.35 | J40: ='Proy. ventas'!K85+'Proy. ventas'!K86+'Proy. ventas'!K87 -> 154 | K40: =J40*$C40 -> 53.9 | L40: ='Proy. ventas'!M85+'Proy. ventas'!M86+'Proy. ventas'!M87 -> 167 | M40: =L40*$C40 -> 58.45 | N40: ='Proy. ventas'!O85+'Proy. ventas'!O86+'Proy. ventas'!O87 -> 181 | O40: =N40*$C40 -> 63.35 | P40: ='Proy. ventas'!Q85+'Proy. ventas'!Q86+'Proy. ventas'!Q87 -> 195 | Q40: =P40*$C40 -> 68.25 | R40: ='Proy. ventas'!S85+'Proy. ventas'!S86+'Proy. ventas'!S87 -> 210 | S40: =R40*$C40 -> 73.5 | T40: ='Proy. ventas'!U85+'Proy. ventas'!U86+'Proy. ventas'!U87 -> 224 | U40: =T40*$C40 -> 78.4 | V40: ='Proy. ventas'!W85+'Proy. ventas'!W86+'Proy. ventas'!W87 -> 239 | W40: =V40*$C40 -> 83.65 | X40: ='Proy. ventas'!Y85+'Proy. ventas'!Y86+'Proy. ventas'!Y87 -> 255 | Y40: =X40*$C40 -> 89.25 | Z40: ='Proy. ventas'!AA85+'Proy. ventas'!AA86+'Proy. ventas'!AA87 -> 272 | AA40: =Z40*$C40 -> 95.2 | AB40: =E40+G40+I40+K40+M40+O40+Q40+S40+U40+W40+Y40+AA40 -> 798.35
B41: Gateway de notificaciones | C41: 0.15 | D41: ='Proy. ventas'!E85+'Proy. ventas'!E86+'Proy. ventas'!E87 -> 115 | E41: =D41*$C41 -> 17.25 | F41: ='Proy. ventas'!G85+'Proy. ventas'!G86+'Proy. ventas'!G87 -> 128 | G41: =F41*$C41 -> 19.2 | H41: ='Proy. ventas'!I85+'Proy. ventas'!I86+'Proy. ventas'!I87 -> 141 | I41: =H41*$C41 -> 21.15 | J41: ='Proy. ventas'!K85+'Proy. ventas'!K86+'Proy. ventas'!K87 -> 154 | K41: =J41*$C41 -> 23.1 | L41: ='Proy. ventas'!M85+'Proy. ventas'!M86+'Proy. ventas'!M87 -> 167 | M41: =L41*$C41 -> 25.05 | N41: ='Proy. ventas'!O85+'Proy. ventas'!O86+'Proy. ventas'!O87 -> 181 | O41: =N41*$C41 -> 27.15 | P41: ='Proy. ventas'!Q85+'Proy. ventas'!Q86+'Proy. ventas'!Q87 -> 195 | Q41: =P41*$C41 -> 29.25 | R41: ='Proy. ventas'!S85+'Proy. ventas'!S86+'Proy. ventas'!S87 -> 210 | S41: =R41*$C41 -> 31.5 | T41: ='Proy. ventas'!U85+'Proy. ventas'!U86+'Proy. ventas'!U87 -> 224 | U41: =T41*$C41 -> 33.6 | V41: ='Proy. ventas'!W85+'Proy. ventas'!W86+'Proy. ventas'!W87 -> 239 | W41: =V41*$C41 -> 35.85 | X41: ='Proy. ventas'!Y85+'Proy. ventas'!Y86+'Proy. ventas'!Y87 -> 255 | Y41: =X41*$C41 -> 38.25 | Z41: ='Proy. ventas'!AA85+'Proy. ventas'!AA86+'Proy. ventas'!AA87 -> 272 | AA41: =Z41*$C41 -> 40.8 | AB41: =E41+G41+I41+K41+M41+O41+Q41+S41+U41+W41+Y41+AA41 -> 342.15
B42: Comisiones de medios de pago | C42: 0.9 | D42: ='Proy. ventas'!E85+'Proy. ventas'!E86+'Proy. ventas'!E87 -> 115 | E42: =D42*$C42 -> 103.5 | F42: ='Proy. ventas'!G85+'Proy. ventas'!G86+'Proy. ventas'!G87 -> 128 | G42: =F42*$C42 -> 115.2 | H42: ='Proy. ventas'!I85+'Proy. ventas'!I86+'Proy. ventas'!I87 -> 141 | I42: =H42*$C42 -> 126.9 | J42: ='Proy. ventas'!K85+'Proy. ventas'!K86+'Proy. ventas'!K87 -> 154 | K42: =J42*$C42 -> 138.6 | L42: ='Proy. ventas'!M85+'Proy. ventas'!M86+'Proy. ventas'!M87 -> 167 | M42: =L42*$C42 -> 150.3 | N42: ='Proy. ventas'!O85+'Proy. ventas'!O86+'Proy. ventas'!O87 -> 181 | O42: =N42*$C42 -> 162.9 | P42: ='Proy. ventas'!Q85+'Proy. ventas'!Q86+'Proy. ventas'!Q87 -> 195 | Q42: =P42*$C42 -> 175.5 | R42: ='Proy. ventas'!S85+'Proy. ventas'!S86+'Proy. ventas'!S87 -> 210 | S42: =R42*$C42 -> 189 | T42: ='Proy. ventas'!U85+'Proy. ventas'!U86+'Proy. ventas'!U87 -> 224 | U42: =T42*$C42 -> 201.6 | V42: ='Proy. ventas'!W85+'Proy. ventas'!W86+'Proy. ventas'!W87 -> 239 | W42: =V42*$C42 -> 215.1 | X42: ='Proy. ventas'!Y85+'Proy. ventas'!Y86+'Proy. ventas'!Y87 -> 255 | Y42: =X42*$C42 -> 229.5 | Z42: ='Proy. ventas'!AA85+'Proy. ventas'!AA86+'Proy. ventas'!AA87 -> 272 | AA42: =Z42*$C42 -> 244.8 | AB42: =E42+G42+I42+K42+M42+O42+Q42+S42+U42+W42+Y42+AA42 -> 2052.9
B43: Reposición de equipamiento no recuperado | C43: 6 | D43: ='Proy. ventas'!E83+'Proy. ventas'!E84 -> 9 | E43: =D43*$C43 -> 54 | F43: ='Proy. ventas'!G83+'Proy. ventas'!G84 -> 9 | G43: =F43*$C43 -> 54 | H43: ='Proy. ventas'!I83+'Proy. ventas'!I84 -> 9 | I43: =H43*$C43 -> 54 | J43: ='Proy. ventas'!K83+'Proy. ventas'!K84 -> 9 | K43: =J43*$C43 -> 54 | L43: ='Proy. ventas'!M83+'Proy. ventas'!M84 -> 9 | M43: =L43*$C43 -> 54 | N43: ='Proy. ventas'!O83+'Proy. ventas'!O84 -> 10 | O43: =N43*$C43 -> 60 | P43: ='Proy. ventas'!Q83+'Proy. ventas'!Q84 -> 10 | Q43: =P43*$C43 -> 60 | R43: ='Proy. ventas'!S83+'Proy. ventas'!S84 -> 11 | S43: =R43*$C43 -> 66 | T43: ='Proy. ventas'!U83+'Proy. ventas'!U84 -> 10 | U43: =T43*$C43 -> 60 | V43: ='Proy. ventas'!W83+'Proy. ventas'!W84 -> 11 | W43: =V43*$C43 -> 66 | X43: ='Proy. ventas'!Y83+'Proy. ventas'!Y84 -> 11 | Y43: =X43*$C43 -> 66 | Z43: ='Proy. ventas'!AA83+'Proy. ventas'!AA84 -> 11 | AA43: =Z43*$C43 -> 66 | AB43: =E43+G43+I43+K43+M43+O43+Q43+S43+U43+W43+Y43+AA43 -> 714
A44: Promoción | B44: Bonificación del alta - Plan Básico | C44: =Hipótesis!$C$58*0.3 -> 7.5 | D44: ='Proy. ventas'!E82 -> 4 | E44: =D44*$C44 -> 30 | F44: ='Proy. ventas'!G82 -> 4 | G44: =F44*$C44 -> 30 | H44: ='Proy. ventas'!I82 -> 4 | I44: =H44*$C44 -> 30 | J44: ='Proy. ventas'!K82 -> 4 | K44: =J44*$C44 -> 30 | L44: ='Proy. ventas'!M82 -> 4 | M44: =L44*$C44 -> 30 | N44: ='Proy. ventas'!O82 -> 4 | O44: =N44*$C44 -> 30 | P44: ='Proy. ventas'!Q82 -> 4 | Q44: =P44*$C44 -> 30 | R44: ='Proy. ventas'!S82 -> 4 | S44: =R44*$C44 -> 30 | T44: ='Proy. ventas'!U82 -> 4 | U44: =T44*$C44 -> 30 | V44: ='Proy. ventas'!W82 -> 4 | W44: =V44*$C44 -> 30 | X44: ='Proy. ventas'!Y82 -> 5 | Y44: =X44*$C44 -> 37.5 | Z44: ='Proy. ventas'!AA82 -> 6 | AA44: =Z44*$C44 -> 45 | AB44: =E44+G44+I44+K44+M44+O44+Q44+S44+U44+W44+Y44+AA44 -> 382.5
B45: Bonificación del alta - Plan Vidriera | C45: =Hipótesis!$C$59*0.3 -> 18 | D45: ='Proy. ventas'!E83 -> 8 | E45: =D45*$C45 -> 144 | F45: ='Proy. ventas'!G83 -> 8 | G45: =F45*$C45 -> 144 | H45: ='Proy. ventas'!I83 -> 8 | I45: =H45*$C45 -> 144 | J45: ='Proy. ventas'!K83 -> 8 | K45: =J45*$C45 -> 144 | L45: ='Proy. ventas'!M83 -> 8 | M45: =L45*$C45 -> 144 | N45: ='Proy. ventas'!O83 -> 8 | O45: =N45*$C45 -> 144 | P45: ='Proy. ventas'!Q83 -> 9 | Q45: =P45*$C45 -> 162 | R45: ='Proy. ventas'!S83 -> 9 | S45: =R45*$C45 -> 162 | T45: ='Proy. ventas'!U83 -> 9 | U45: =T45*$C45 -> 162 | V45: ='Proy. ventas'!W83 -> 9 | W45: =V45*$C45 -> 162 | X45: ='Proy. ventas'!Y83 -> 9 | Y45: =X45*$C45 -> 162 | Z45: ='Proy. ventas'!AA83 -> 9 | AA45: =Z45*$C45 -> 162 | AB45: =E45+G45+I45+K45+M45+O45+Q45+S45+U45+W45+Y45+AA45 -> 1836
B46: Bonificación del alta - Plan Cadena | C46: =Hipótesis!$C$60*0.3 -> 75 | D46: ='Proy. ventas'!E84 -> 1 | E46: =D46*$C46 -> 75 | F46: ='Proy. ventas'!G84 -> 1 | G46: =F46*$C46 -> 75 | H46: ='Proy. ventas'!I84 -> 1 | I46: =H46*$C46 -> 75 | J46: ='Proy. ventas'!K84 -> 1 | K46: =J46*$C46 -> 75 | L46: ='Proy. ventas'!M84 -> 1 | M46: =L46*$C46 -> 75 | N46: ='Proy. ventas'!O84 -> 2 | O46: =N46*$C46 -> 150 | P46: ='Proy. ventas'!Q84 -> 1 | Q46: =P46*$C46 -> 75 | R46: ='Proy. ventas'!S84 -> 2 | S46: =R46*$C46 -> 150 | T46: ='Proy. ventas'!U84 -> 1 | U46: =T46*$C46 -> 75 | V46: ='Proy. ventas'!W84 -> 2 | W46: =V46*$C46 -> 150 | X46: ='Proy. ventas'!Y84 -> 2 | Y46: =X46*$C46 -> 150 | Z46: ='Proy. ventas'!AA84 -> 2 | AA46: =Z46*$C46 -> 150 | AB46: =E46+G46+I46+K46+M46+O46+Q46+S46+U46+W46+Y46+AA46 -> 1275
B47: Incentivo del programa de referidos | C47: 10 | D47: =ROUND(('Proy. ventas'!E82+'Proy. ventas'!E83+'Proy. ventas'!E84)*0.3,0) -> 4 | E47: =D47*$C47 -> 40 | F47: =ROUND(('Proy. ventas'!G82+'Proy. ventas'!G83+'Proy. ventas'!G84)*0.3,0) -> 4 | G47: =F47*$C47 -> 40 | H47: =ROUND(('Proy. ventas'!I82+'Proy. ventas'!I83+'Proy. ventas'!I84)*0.3,0) -> 4 | I47: =H47*$C47 -> 40 | J47: =ROUND(('Proy. ventas'!K82+'Proy. ventas'!K83+'Proy. ventas'!K84)*0.3,0) -> 4 | K47: =J47*$C47 -> 40 | L47: =ROUND(('Proy. ventas'!M82+'Proy. ventas'!M83+'Proy. ventas'!M84)*0.3,0) -> 4 | M47: =L47*$C47 -> 40 | N47: =ROUND(('Proy. ventas'!O82+'Proy. ventas'!O83+'Proy. ventas'!O84)*0.3,0) -> 4 | O47: =N47*$C47 -> 40 | P47: =ROUND(('Proy. ventas'!Q82+'Proy. ventas'!Q83+'Proy. ventas'!Q84)*0.3,0) -> 4 | Q47: =P47*$C47 -> 40 | R47: =ROUND(('Proy. ventas'!S82+'Proy. ventas'!S83+'Proy. ventas'!S84)*0.3,0) -> 5 | S47: =R47*$C47 -> 50 | T47: =ROUND(('Proy. ventas'!U82+'Proy. ventas'!U83+'Proy. ventas'!U84)*0.3,0) -> 4 | U47: =T47*$C47 -> 40 | V47: =ROUND(('Proy. ventas'!W82+'Proy. ventas'!W83+'Proy. ventas'!W84)*0.3,0) -> 5 | W47: =V47*$C47 -> 50 | X47: =ROUND(('Proy. ventas'!Y82+'Proy. ventas'!Y83+'Proy. ventas'!Y84)*0.3,0) -> 5 | Y47: =X47*$C47 -> 50 | Z47: =ROUND(('Proy. ventas'!AA82+'Proy. ventas'!AA83+'Proy. ventas'!AA84)*0.3,0) -> 5 | AA47: =Z47*$C47 -> 50 | AB47: =E47+G47+I47+K47+M47+O47+Q47+S47+U47+W47+Y47+AA47 -> 520
B55: TOTAL | E55: =SUM(E38:E47) -> 744 | G55: =SUM(G38:G47) -> 762.2 | I55: =SUM(I38:I47) -> 780.4 | K55: =SUM(K38:K47) -> 798.6 | M55: =SUM(M38:M47) -> 816.8 | O55: =SUM(O38:O47) -> 937.4 | Q55: =SUM(Q38:Q47) -> 900 | S55: =SUM(S38:S47) -> 1032 | U55: =SUM(U38:U47) -> 940.6 | W55: =SUM(W38:W47) -> 1072.6 | Y55: =SUM(Y38:Y47) -> 1117.5 | AA55: =SUM(AA38:AA47) -> 1163.8 | AB55: =SUM(AB38:AB47) -> 11065.9
B58: Costos variables - Año 2028
A59: Rubro | B59: Descripción | C59: Costo unitario | D59: Enero | F59: Febrero | H59: Marzo | J59: Abril | L59: Mayo | N59: Junio | P59: Julio | R59: Agosto | T59: Septiembre | V59: Octubre | X59: Noviembre | Z59: Diciembre | AB59: Total anual
D60: Cant. | E60: Costo | F60: Cant. | G60: Costo | H60: Cant. | I60: Costo | J60: Cant. | K60: Costo | L60: Cant. | M60: Costo | N60: Cant. | O60: Costo | P60: Cant. | Q60: Costo | R60: Cant. | S60: Costo | T60: Cant. | U60: Costo | V60: Cant. | W60: Costo | X60: Cant. | Y60: Costo | Z60: Cant. | AA60: Costo
A61: Operación | B61: Comisión del vendedor por alta concretada | C61: 15 | D61: ='Proy. ventas'!E144+'Proy. ventas'!E145+'Proy. ventas'!E146 -> 20 | E61: =D61*$C61 -> 300 | F61: ='Proy. ventas'!G144+'Proy. ventas'!G145+'Proy. ventas'!G146 -> 20 | G61: =F61*$C61 -> 300 | H61: ='Proy. ventas'!I144+'Proy. ventas'!I145+'Proy. ventas'!I146 -> 20 | I61: =H61*$C61 -> 300 | J61: ='Proy. ventas'!K144+'Proy. ventas'!K145+'Proy. ventas'!K146 -> 20 | K61: =J61*$C61 -> 300 | L61: ='Proy. ventas'!M144+'Proy. ventas'!M145+'Proy. ventas'!M146 -> 20 | M61: =L61*$C61 -> 300 | N61: ='Proy. ventas'!O144+'Proy. ventas'!O145+'Proy. ventas'!O146 -> 20 | O61: =N61*$C61 -> 300 | P61: ='Proy. ventas'!Q144+'Proy. ventas'!Q145+'Proy. ventas'!Q146 -> 20 | Q61: =P61*$C61 -> 300 | R61: ='Proy. ventas'!S144+'Proy. ventas'!S145+'Proy. ventas'!S146 -> 20 | S61: =R61*$C61 -> 300 | T61: ='Proy. ventas'!U144+'Proy. ventas'!U145+'Proy. ventas'!U146 -> 20 | U61: =T61*$C61 -> 300 | V61: ='Proy. ventas'!W144+'Proy. ventas'!W145+'Proy. ventas'!W146 -> 20 | W61: =V61*$C61 -> 300 | X61: ='Proy. ventas'!Y144+'Proy. ventas'!Y145+'Proy. ventas'!Y146 -> 20 | Y61: =X61*$C61 -> 300 | Z61: ='Proy. ventas'!AA144+'Proy. ventas'!AA145+'Proy. ventas'!AA146 -> 18 | AA61: =Z61*$C61 -> 270 | AB61: =E61+G61+I61+K61+M61+O61+Q61+S61+U61+W61+Y61+AA61 -> 3570
...

Sheet Costos RRHH
E1: Estructura de costos de RRHH
B4: Evolución de la participación | H4: Costos de RRHH - Totales
B5: 2026 | C5: 2027 | D5: 2028 | H5: 2026 | I5: 2027 | J5: 2028
B6: =Hipótesis!C24 -> 0.03 | C6: =Hipótesis!C25 -> 0.08 | D6: =Hipótesis!C26 -> 0.15 | H6: =O39 -> 122984.64 | I6: =O57 -> 150323.36 | J6: =O75 -> 183152.53
B7: =Hipótesis!D24 -> 48960 | C7: =Hipótesis!D25 -> 130560 | D7: =Hipótesis!D26 -> 244800
B13: Costo mensual por puesto (USD)
B14: Área | C14: Puesto | D14: Sueldo bruto | E14: Jubilación | F14: Ley 19.032 | G14: Obra social | H14: F. Nac. Empleo | I14: Seg. de Vida | J14: ART | K14: Total aportes | L14: Costo mensual para la empresa
B15: Alícuotas patronales | E15: 0.1047 | F15: 0.0154 | G15: 0.06 | H15: 0.0092 | I15: 1.2 | J15: 0.03
B16: Gerencia | C16: Gerente General (Fundador / CEO) | D16: 2000 | E16: =$D16*$E$15 -> 209.4 | F16: =$D16*$F$15 -> 30.8 | G16: =$D16*$G$15 -> 120 | H16: =$D16*$H$15 -> 18.4 | I16: =$I$15 -> 1.2 | J16: =$D16*$J$15 -> 60 | K16: =SUM(E16:J16) -> 439.8 | L16: =D16+K16 -> 2439.8
C17: Gerente de Sistemas (Fundador / CTO) | D17: 2000 | E17: =$D17*$E$15 -> 209.4 | F17: =$D17*$F$15 -> 30.8 | G17: =$D17*$G$15 -> 120 | H17: =$D17*$H$15 -> 18.4 | I17: =$I$15 -> 1.2 | J17: =$D17*$J$15 -> 60 | K17: =SUM(E17:J17) -> 439.8 | L17: =D17+K17 -> 2439.8
B18: Sistemas | C18: Desarrollador | D18: 1800 | E18: =$D18*$E$15 -> 188.46 | F18: =$D18*$F$15 -> 27.72 | G18: =$D18*$G$15 -> 108 | H18: =$D18*$H$15 -> 16.56 | I18: =$I$15 -> 1.2 | J18: =$D18*$J$15 -> 54 | K18: =SUM(E18:J18) -> 395.94 | L18: =D18+K18 -> 2195.94
C19: Técnico de instalación y soporte | D19: 1100 | E19: =$D19*$E$15 -> 115.17 | F19: =$D19*$F$15 -> 16.94 | G19: =$D19*$G$15 -> 66 | H19: =$D19*$H$15 -> 10.12 | I19: =$I$15 -> 1.2 | J19: =$D19*$J$15 -> 33 | K19: =SUM(E19:J19) -> 242.43 | L19: =D19+K19 -> 1342.43
